Workbook
Name AHUArrangment: [1]Data!$B$6
Name AngleThkO: [1]Data!$B$9
Name BuildForDXFOutput: Data!$B$15
Name Construction: [1]Data!$B$5
Name FLOOR_X_LENGTH: Calcs!$C$2
Name FLOOR_Z_LENGTH: Calcs!$C$3
Name FloorXLength: Data!$B$3
Name FloorZLength: Data!$B$4
Name FrontOverlapLength: Data!$B$8
Name HasFrontOverlap: Data!$B$7
Name HasLeftOverlap: Data!$B$11
Name HasRearOverlap: Data!$B$9
Name HasRightOverlap: Data!$B$13
Name LeftOverlapLength: Data!$B$12
Name Length: [1]Data!$B$3
Name MAT_LOOKUP: Calcs!$C$4
Name MATERIALSTYLE: [1]Data!$B$4
Name MaterialType: Data!$B$5
Name MaxBHHoleSpc: '[1]Excel Calcs'!$L$5
Name MaxBHHoleSpc_X: [1]Data!$B$8
Name MaxBHHoleSpc_Y: [1]Data!#REF!
Name Mtl_Gauge: Data!$B$6
Name NotchFront: Data!#REF!
Name NotchFrontLength: Data!#REF!
Name NotchLeft: Data!#REF!
Name NotchLeftLength: Data!#REF!
Name PanelLinerMaterialGage: Data!$B$6
Name RearOverlapLength: Data!$B$10
Name RightOverlapLength: Data!$B$14
Name Tier: [1]Data!$B$7
Name Width: [1]Data!#REF!

Sheet Sheet1
A1: Parameter | B1: Value | C1: UOM | D1: Comments
A2: FloorXLength | B2: =FLOOR_X_LENGTH -> 4.25 | C2: in | D2: Length of Floor along X-Axis
A3: FloorZLength | B3: =FLOOR_Z_LENGTH -> 89.5 | C3: in | D3: Length of Floor along Z-Axis
A4: MaterialThickness | B4: =Calcs!C5 -> 0.05601 | C4: in | D4: Thickness of floor
A5: JoggleHeight | B5: =Calcs!C6 -> 0.06899 | C5: in | D5: Joggle Height
A6: HasRightJoggle | B6: =Calcs!C7 -> 0 | C6: ul | D6: Right Joggle
A7: RightJoggleLength | B7: =Calcs!C8 -> 1.5 | C7: in | D7: Right Joggle Length
A8: HasRearJoggle | B8: =Calcs!C9 -> 0 | C8: ul | D8: Rear Joggle
A9: RearJoggleLength | B9: =Calcs!C10 -> 1.5 | C9: in | D9: Rear Joggle Length
A10: HasLeftJoggle | B10: =Calcs!C11 -> 0 | C10: ul | D10: Left Joggle
A11: LeftJoggleLength | B11: =Calcs!C12 -> 1.5 | C11: in | D11: Left Joggle Length
A12: HasFrontJoggle | B12: =Calcs!C13 -> 0 | C12: ul | D12: Front Joggle
A13: FrontJoggleLength | B13: =Calcs!C14 -> 1.5 | C13: in | D13: Front Joggle Length

Sheet Data
A1: INPUTS
A2: Parameter | B2: Value | C2: Description
A3: FloorXLength | B3: 4.25 | C3: Length of Floor along X-Axis
A4: FloorZLength | B4: 89.5 | C4: Length of Floor along Z-Axis
A5: MaterialType | B5: STL GALV | C5: Material Style
A6: Mtl_Gauge | B6: 16 | C6: Any vaild gauge thickness
A7: HasFrontOverlap | B7: NO | C7: FRONT_JOGGLE
A8: FrontOverlapLength | B8: 1.5 | C8: FRONT_JOGGLE_LENGTH
A9: HasRearOverlap | B9: NO | C9: REAR_JOGGLE
A10: RearOverlapLength | B10: 1.5 | C10: REAR_JOGGLE_LENGTH
A11: HasLeftOverlap | B11: NO | C11: LEFT_JOGGLE
A12: LeftOverlapLength | B12: 1.5 | C12: LEFT_JOGGLE_LENGTH
A13: HasRightOverlap | B13: NO | C13: RIGHT_JOGGLE
A14: RightOverlapLength | B14: 1.5 | C14: RIGHT_JOGGLE_LENGTH
A15: BuildForDXFOutput | B15: NO | C15: BuildForDXFOutput

Sheet Calcs
B1: Parameter | C1: Value
B2: FLOOR_X_LENGTH | C2: =FloorXLength - (IF(AND(HasRearOverlap="YES"),RearOverlapLength,0))-(IF(AND(HasFrontOverlap="YES"),FrontOverlapLength,0)) -> 4.25
B3: FLOOR_Z_LENGTH | C3: =FloorZLength - (IF(AND(HasRightOverlap="YES"),RightOverlapLength, 0)) - (IF(AND(HasLeftOverlap="YES"),LeftOverlapLength,0)) -> 89.5
B4: MAT_LOOKUP | C4: =CONCATENATE(Mtl_Gauge, MaterialType) -> 16STL GALV
B5: MaterialThickness | C5: =VLOOKUP(MAT_LOOKUP,Material!A5:H117, 8, FALSE) -> 0.05601
B6: JoggleHeight | C6: =0.125-C5 -> 0.06899
B7: HasRightJoggle | C7: =IF(HasRightOverlap="YES",1,0) -> 0
B8: RightJoggleLength | C8: =RightOverlapLength -> 1.5
B9: HasRearJoggle | C9: =IF( HasRearOverlap = "YES",1,0) -> 0
B10: RearJoggleLength | C10: =RearOverlapLength -> 1.5
B11: HasLeftJoggle | C11: =IF(HasLeftOverlap="YES",1,0) -> 0
B12: LeftJoggleLength | C12: =LeftOverlapLength -> 1.5
B13: HasFrontJoggle | C13: =IF(HasFrontOverlap="YES",1,0) -> 0
B14: FrontJoggleLength | C14: =FrontOverlapLength -> 1.5

Sheet Material
B1: Solution Project, Raw material codes and calculations, Sheet or Coil stock, Square Foot
D2: Mat'l Group | E2: Metal Gauge | F2: Metal Thickness Min. | G2: Design Thickness (Ref) | H2: Inventor Thickness Key_PK | I2: Active Product "XT" | J2: Active Product "YC" | K2: Mapics Part Number | L2: Material description | M2: Material Type | N2: York "R" Std | O2: Max Cut Size | P2: Unit of Measure | Q2: Inventor Material Designation | R2: "DXF" Mat'l Data (must be 8 characters for Mapics) | S2: Hole Size / Texture | T2: Staggered Centers
A3: MAT_LOOKUP | D3: MAT_GRP | E3: MAT_GA | F3: MAT_MINT | G3: MAT_DEST | H3: MAT_KEYT | I3: MAT_XT | J3: MAT_YC | K3: MAT_PNUM | L3: MAT_DESC | M3: MAT_TYPE | N3: MAT_RSTD | O3: MAT_CUT | P3: MAT_UMSR | Q3: MAT_DESG | R3: MAT_DXF | S3: MAT_HLSZ | T3: MAT_STG
C4: Sheet Products, Solid
A5: =CONCATENATE(E5,Q5) -> 8STL GALV | D5: Sheet, G90 | E5: 8 | F5: .156 | G5: 0.156 | H5: 0.15601 | I5: XT | J5: YC | K5: 005 06145 008 | L5: Galvanized Steel | M5: G90 | N5: R259 w/ note 4 | O5: 48 X 144 | P5: SF | Q5: STL GALV | R5: GLVS157- | S5: N/A | T5: N/A
A6: =CONCATENATE(E6,Q6) -> 10STL GALV | D6: Sheet, G90 | E6: 10 | F6: .125 | G6: 0.126 | H6: 0.12601 | I6: - | J6: YC | K6: 005 06145 010 | L6: Galvanized Steel | M6: G90 | N6: R259 w/ note 4 | O6: 48 X 144 | P6: SF | Q6: STL GALV | R6: GLVS126- | S6: N/A | T6: N/A
A7: =CONCATENATE(E7,Q7) -> 12STL GALV | D7: Sheet, G90 | E7: 12 | F7: .096 | G7: 0.097 | H7: 0.09701 | I7: - | J7: YC | K7: 005 06145 012 | L7: Galvanized Steel | M7: G90 | N7: R259 w/ note 4 | O7: 60 X 144 | P7: SF | Q7: STL GALV | R7: GLVS097- | S7: N/A | T7: N/A
A8: =CONCATENATE(E8,Q8) -> 14STL GALV | D8: Sheet, G90 | E8: 14 | F8: .069 | G8: 0.07 | H8: 0.07001 | I8: - | J8: YC | K8: 005 06145 014 | L8: Galvanized Steel | M8: G90 | N8: R259 w/ note 4 | O8: 60 X 144 | P8: SF | Q8: STL GALV | R8: GLVS070- | S8: N/A | T8: N/A
A9: =CONCATENATE(E9,Q9) -> 16STL GALV | D9: Sheet, G90 | E9: 16 | F9: .055 | G9: 0.056 | H9: 0.05601 | I9: XT | J9: YC | K9: 005 06145 016 | L9: Galvanized Steel | M9: G90 | N9: R259 w/ note 4 | O9: 60 X 144 | P9: SF | Q9: STL GALV | R9: GLVS056A | S9: N/A | T9: N/A
A10: =CONCATENATE(E10,Q10) -> 18STL GALV | D10: Sheet, G90 | E10: 18 | F10: .044 | G10: 0.045 | H10: 0.04501 | I10: XT | J10: YC | K10: 005 06145 018 | L10: Galvanized Steel | M10: G90 | N10: R259 w/ note 4 | O10: 60 X 144 | P10: SF | Q10: STL GALV | R10: GLVS045A | S10: N/A | T10: N/A
A11: =CONCATENATE(E11,Q11) -> 20STL GALV | D11: Sheet, G90 | E11: 20 | F11: .033 | G11: 0.034 | H11: 0.03401 | I11: XT | J11: YC | K11: 005 06145 020 | L11: Galvanized Steel | M11: G90 | N11: R259 w/ note 4 | O11: 60 X 144 | P11: SF | Q11: STL GALV | R11: GLVS034- | S11: N/A | T11: N/A
A12: =CONCATENATE(E12,Q12) -> 22STL GALV | D12: Sheet, G90 | E12: 22 | F12: .028 | G12: 0.028 | H12: 0.02801 | I12: - | J12: YC | K12: 005 06145 022 | L12: Galvanized Steel | M12: G90 | N12: R259 w/ note 4 | O12: 60 X 144 | P12: SF | Q12: STL GALV | R12: GLVS028- | S12: N/A | T12: N/A
A13: =CONCATENATE(E13,Q13) -> 24STL GALV | D13: Sheet, G90 | E13: 24 | F13: .022 | G13: 0.022 | H13: 0.02201 | I13: XT | J13: YC | K13: 005 06145 024 | L13: Galvanized Steel | M13: G90 | N13: R259 w/ note 4 | O13: 60 X 144 | P13: SF | Q13: STL GALV | R13: GLVS022- | S13: N/A | T13: N/A
A14: =CONCATENATE(E14,Q14) -> 16STL GALV2 | D14: Roll Form Coil | E14: 16 | F14: .055 | G14: 0.056 | H14: 0.05605 | I14: - | J14: YC | K14: 001 07591 467 | L14: Channel,Rf,16ga,Glv,4.67w_Flat, YC 2" Housing Channel | M14: G40 | N14: R259 w/ note 4 | O14: 4.67 X Lg | P14: SF | Q14: STL GALV2 | R14: GLVS056C | S14: N/A | T14: N/A
A15: =CONCATENATE(E15,Q15) -> 16STL GALV3 | D15: Roll Form Coil | E15: 16 | F15: .055 | G15: 0.056 | H15: 0.05606 | I15: - | J15: YC | K15: 001 07591 567 | L15: Channel,Rf,16ga,Glv,5.67w_Flat, YC 3" Housing Channel | M15: G40 | N15: R259 w/ note 4 | O15: 5.67 X Lg | P15: SF | Q15: STL GALV3 | R15: GLVS056D | S15: N/A | T15: N/A
A16: =CONCATENATE(E16,Q16) -> 16STL GALV4 | D16: Roll Form Coil | E16: 16 | F16: .055 | G16: 0.056 | H16: 0.05607 | I16: - | J16: YC | K16: 001 07591 667 | L16: Channel,Rf,16ga,Glv,6.67w_Flat, YC 4" Housing Channel | M16: G40 | N16: R259 w/ note 4 | O16: 6.67 X Lg | P16: SF | Q16: STL GALV4 | R16: GLVS056E | S16: N/A | T16: N/A
A17: =CONCATENATE(E17,Q17) -> 18STL GALVS | D17: Roll Form Coil | E17: 18 | F17: .044 | G17: 0.045 | H17: 0.04502 | I17: XT | J17: - | K17: 005 06160 001 | L17: Galvanized Steel, Coil, XT Seam Cap | M17: G90 | N17: R259 w/ note 4 | O17: 2.491 X Lg | P17: SF | Q17: STL GALVS | R17: GLVS045B | S17: N/A | T17: N/A
A18: =CONCATENATE(E18,Q18) -> 16STL GALVR | D18: Roll Form Coil | E18: 16 | F18: .055 | G18: 0.056 | H18: 0.05602 | I18: XT | J18: - | K18: 005 06161 001 | L18: Galvanized Steel, Coil, XT Raceway | M18: G90 | N18: R259 w/ note 4 | O18: 12.62 X Lg | P18: SF | Q18: STL GALVR | R18: GLVS056B | S18: N/A | T18: N/A
A19: =CONCATENATE(E19,Q19) -> 14STL GALV PPG | D19: Sheet, Pre-Paint | E19: 14 | F19: .069 | G19: 0.07 | H19: 0.07003 | I19: - | J19: YC | K19: 005 07110 014 | L19: Sheet,Pre-Paint,Gray,14ga | M19: P-Paint | N19: M-310 | O19: 48 x Lg | P19: SF | Q19: STL GALV PPG | R19: GLVPP070A | S19: Gray Paint | T19: N/A
A20: =CONCATENATE(E20,Q20) -> 16STL GALV PPG | D20: Sheet, Pre-Paint | E20: 16 | F20: .055 | G20: 0.056 | H20: 0.05603 | I20: - | J20: YC | K20: 005 07110 016 | L20: Sheet,Pre-Paint,Gray,16ga | M20: P-Paint | N20: M-310 | O20: 48 x Lg | P20: SF | Q20: STL GALV PPG | R20: GLVPP056A | S20: Gray Paint | T20: N/A
A21: =CONCATENATE(E21,Q21) -> 16STL GALV PPC | D21: Sheet, Pre-Paint | E21: 16 | F21: .055 | G21: 0.056 | H21: 0.05604 | I21: - | J21: YC | K21: 005 07110 116 | L21: Sheet,Pre-Paint,Champagne,16ga | M21: P-Paint | N21: M-310 | O21: 48 x Lg | P21: SF | Q21: STL GALV PPC | R21: GLVPP056B | S21: Champagne Paint | T21: N/A
A22: =CONCATENATE(E22,Q22) -> 18STL GALV PPW | D22: Sheet, Pre-Paint | E22: 18 | F22: .044 | G22: 0.045 | H22: 0.04503 | I22: - | J22: YC | K22: 005 07110 117 | L22: Sheet,Pre-Paint,Msftwhite,18ga | M22: P-Paint | N22: M-310 | O22: 48 x Lg | P22: SF | Q22: STL GALV PPW | R22: GLVPP045A | S22: Msftwhite Paint | T22: N/A
A23: =CONCATENATE(E23,Q23) -> 18STL GALV PPC | D23: Sheet, Pre-Paint | E23: 18 | F23: .044 | G23: 0.045 | H23: 0.04504 | I23: - | J23: YC | K23: 005 07110 118 | L23: Sheet,Pre-Paint,Champagne,18ga | M23: P-Paint | N23: M-310 | O23: 48 x Lg | P23: SF | Q23: STL GALV PPC | R23: GLVPP045B | S23: Champagne Paint | T23: N/A
A24: =CONCATENATE(E24,Q24) -> 20STL GALV PPC | D24: Sheet, Pre-Paint | E24: 20 | F24: .033 | G24: 0.034 | H24: 0.03404 | I24: XT | J24: YC | K24: 005 07110 120 | L24: Sheet,Pre-Paint,Champagne,20ga | M24: P-Paint | N24: R-14 | O24: 48 x Lg | P24: SF | Q24: STL GALV PPC | R24: GLPP034A | S24: Champagne Paint | T24: N/A
A25: =CONCATENATE(E25,Q25) -> 10STL HOT ROLL | D25: Sheet, HR | E25: 10 | F25: .127 | G25: 0.127 | H25: 0.12701 | I25: - | J25: YC | K25: 005 07113 010 | L25: Sheet,Hot-Rolled,10ga | M25: HR | N25: - | O25: 48 X 144 | P25: SF | Q25: STL HOT ROLL | R25: STLHR127A | S25: Hot-Rolled | T25: N/A
A26: =CONCATENATE(E26,Q26) -> 11STL HOT ROLL | D26: Sheet, HR | E26: 11 | F26: .112 | G26: 0.112 | H26: 0.11201 | I26: - | J26: YC | K26: 005 07113 011 | L26: Sheet,Hot-Rolled,11ga | M26: HR | N26: - | O26: 48 X 96 | P26: SF | Q26: STL HOT ROLL | R26: STLHR112A | S26: Hot-Rolled | T26: N/A
A27: =CONCATENATE(E27,Q27) -> 12STL HOT ROLL | D27: Sheet, HR | E27: 12 | F27: .097 | G27: 0.097 | H27: 0.09704 | I27: - | J27: YC | K27: 005 07113 012 | L27: Sheet,Hot-Rolled,12ga | M27: HR | N27: - | O27: 48 X 96 | P27: SF | Q27: STL HOT ROLL | R27: STLHR097A | S27: Hot-Rolled | T27: N/A
A28: =CONCATENATE(E28,Q28) -> 14STL HOT ROLL | D28: Sheet, HR | E28: 14 | F28: .068 | G28: 0.068 | H28: 0.06801 | I28: - | J28: YC | K28: 005 07113 014 | L28: Sheet,Hot-Rolled,14ga | M28: HR | N28: - | O28: 48 X 120 | P28: SF | Q28: STL HOT ROLL | R28: STLHR068A | S28: Hot-Rolled | T28: N/A
A29: =CONCATENATE(E29,Q29) -> 20ALM SHT | D29: Sheet, AL | E29: 20 | F29: .040 | G29: 0.04 | H29: 0.04001 | I29: - | J29: YC | K29: 008 02570 040 | L29: Sheet,Al,3003h14,.040 | M29: AL | N29: R-777 | O29: 48 x 144 | P29: SF | Q29: ALM SHT | R29: ALUS040A | S29: N/A | T29: N/A
A30: =CONCATENATE(E30,Q30) -> 18ALM SHT | D30: Sheet, AL | E30: 18 | F30: .050 | G30: 0.05 | H30: 0.05003 | I30: - | J30: YC | K30: 008 02570 050 | L30: Sheet,Al,3003h14,.050 | M30: AL | N30: R-777 | O30: 48 x 144 | P30: SF | Q30: ALM SHT | R30: ALUS050A | S30: N/A | T30: N/A
A31: =CONCATENATE(E31,Q31) -> 16ALM SHT | D31: Sheet, AL | E31: 16 | F31: .063 | G31: 0.063 | H31: 0.06301 | I31: - | J31: YC | K31: 008 02570 063 | L31: Sheet,Al,3003h14,.063 | M31: AL | N31: R-777 | O31: 48 x 144 | P31: SF | Q31: ALM SHT | R31: ALUS063A | S31: N/A | T31: N/A
A32: =CONCATENATE(E32,Q32) -> 14ALM SHT | D32: Sheet, AL | E32: 14 | F32: .080 | G32: 0.08 | H32: 0.08001 | I32: - | J32: YC | K32: 008 02570 080 | L32: Sheet,Al,3003h14,.080 | M32: AL | N32: R-777 | O32: 48 x 144 | P32: SF | Q32: ALM SHT | R32: ALUS080A | S32: N/A | T32: N/A
A33: =CONCATENATE(E33,Q33) -> 12ALM SHT | D33: Sheet, AL | E33: 12 | F33: .090 | G33: 0.09 | H33: 0.09001 | I33: - | J33: YC | K33: 008 02570 090 | L33: Sheet,Al,3003h14,.090 | M33: AL | N33: R-777 | O33: 48 x 144 | P33: SF | Q33: ALM SHT | R33: ALUS090A | S33: N/A | T33: N/A
A34: =CONCATENATE(E34,Q34) -> 10ALM SHT | D34: Sheet, AL | E34: 10 | F34: .125 | G34: 0.125 | H34: 0.12501 | I34: - | J34: YC | K34: 008 02570 125 | L34: Sheet,Al,3003h14,.125 | M34: AL | N34: R-777 | O34: 48 x 144 | P34: SF | Q34: ALM SHT | R34: ALUS125A | S34: N/A | T34: N/A
A35: =CONCATENATE(E35,Q35) -> 8ALM SHT | D35: Sheet, AL | E35: 8 | F35: .190 | G35: 0.19 | H35: 0.19001 | I35: - | J35: YC | K35: 008 02570 190 | L35: Sheet,Al,3003h14,.190 | M35: AL | N35: R-777 | O35: 48 x 144 | P35: SF | Q35: ALM SHT | R35: ALUS190A | S35: N/A | T35: N/A
... A38: =CONCATENATE(E38,Q38) -> 12SST304 | D38: Sheet, SST | E38: 12 | F38: .105 | G38: 0.105 | H38: 0.10501 | I38: XT | J38: YC | K38: 005 06146 012 | L38: Stainless steel | M38: 304 | N38: R52 | O38: 60 X 144 | P38: SF | Q38: SST304 | R38: SSTS105- | S38: N/A | T38: N/A
A39: =CONCATENATE(E39,Q39) -> 14SST304 | D39: Sheet, SST | E39: 14 | F39: .075 | G39: 0.075 | H39: 0.07501 | I39: XT | J39: YC | K39: 005 06146 014 | L39: Stainless steel | M39: 304 | N39: R52 | O39: 60 X 144 | P39: SF | Q39: SST304 | R39: SSTS075- | S39: N/A | T39: N/A
A40: =CONCATENATE(E40,Q40) -> 16SST304 | D40: Sheet, SST | E40: 16 | F40: .060 | G40: 0.06 | H40: 0.06001 | I40: XT | J40: YC | K40: 005 06146 016 | L40: Stainless steel | M40: 304 | N40: R52 | O40: 60 X 144 | P40: SF | Q40: SST304 | R40: SSTS060- | S40: N/A | T40: N/A
A41: =CONCATENATE(E41,Q41) -> 18SST304 | D41: Sheet, SST | E41: 18 | F41: .048 | G41: 0.048 | H41: 0.04801 | I41: XT | J41: YC | K41: 005 06146 018 | L41: Stainless steel | M41: 304 | N41: R52 | O41: 60 X 144 | P41: SF | Q41: SST304 | R41: SSTS048- | S41: N/A | T41: N/A
A42: =CONCATENATE(E42,Q42) -> 20SST304 | D42: Sheet, SST | E42: 20 | F42: .035 | G42: 0.035 | H42: 0.03501 | I42: XT | J42: YC | K42: 005 06146 020 | L42: Stainless steel | M42: 304 | N42: R52 | O42: 60 X 144 | P42: SF | Q42: SST304 | R42: SSTS035- | S42: N/A | T42: N/A
...

Sheet Revision List
A1: Revision | B1: Date | C1: Description | D1: By | E1: ECN Number
A2: A | B2: 43053 | C2: NEW | D2: MH | E2: -
A3: B | B3: 45183 | C3: Updated Material List to UnCo - 006 Latest Version | D3: DML | E3: 23-11436
